{
 "cells": [
  {
   "cell_type": "code",
   "execution_count": 1,
   "metadata": {},
   "outputs": [],
   "source": [
    "from tensorflow.keras.preprocessing.text import one_hot"
   ]
  },
  {
   "cell_type": "code",
   "execution_count": 2,
   "metadata": {},
   "outputs": [],
   "source": [
    "### sentences\n",
    "sent=[  'the glass of milk',\n",
    "     'the glass of juice',\n",
    "     'the cup of tea',\n",
    "    'I am a good boy',\n",
    "     'I am a good developer',\n",
    "     'understand the meaning of words',\n",
    "     'your videos are good',]"
   ]
  },
  {
   "cell_type": "code",
   "execution_count": 3,
   "metadata": {},
   "outputs": [
    {
     "data": {
      "text/plain": [
       "['the glass of milk',\n",
       " 'the glass of juice',\n",
       " 'the cup of tea',\n",
       " 'I am a good boy',\n",
       " 'I am a good developer',\n",
       " 'understand the meaning of words',\n",
       " 'your videos are good']"
      ]
     },
     "execution_count": 3,
     "metadata": {},
     "output_type": "execute_result"
    }
   ],
   "source": [
    "sent"
   ]
  },
  {
   "cell_type": "code",
   "execution_count": 4,
   "metadata": {},
   "outputs": [],
   "source": [
    "## Define the vocabulary size\n",
    "voc_size=10000"
   ]
  },
  {
   "cell_type": "code",
   "execution_count": 5,
   "metadata": {},
   "outputs": [
    {
     "data": {
      "text/plain": [
       "['the glass of milk',\n",
       " 'the glass of juice',\n",
       " 'the cup of tea',\n",
       " 'I am a good boy',\n",
       " 'I am a good developer',\n",
       " 'understand the meaning of words',\n",
       " 'your videos are good']"
      ]
     },
     "execution_count": 5,
     "metadata": {},
     "output_type": "execute_result"
    }
   ],
   "source": [
    "sent"
   ]
  },
  {
   "cell_type": "code",
   "execution_count": 6,
   "metadata": {},
   "outputs": [
    {
     "data": {
      "text/plain": [
       "[[9316, 6867, 9597, 4588],\n",
       " [9316, 6867, 9597, 4372],\n",
       " [9316, 8449, 9597, 4096],\n",
       " [2041, 3550, 917, 4338, 8682],\n",
       " [2041, 3550, 917, 4338, 521],\n",
       " [7337, 9316, 2472, 9597, 4527],\n",
       " [805, 9120, 9538, 4338]]"
      ]
     },
     "execution_count": 6,
     "metadata": {},
     "output_type": "execute_result"
    }
   ],
   "source": [
    "#One-hot representation using list comprehension\n",
    "one_hot_repr=[one_hot(words,voc_size)for words in sent]\n",
    "one_hot_repr"
   ]
  },
  {
   "cell_type": "code",
   "execution_count": 7,
   "metadata": {},
   "outputs": [],
   "source": [
    "## word Embedding Representation\n",
    "\n",
    "from tensorflow.keras.layers import Embedding\n",
    "#from tensorflow.keras.processing.sequence import pad_sequences\n",
    "from tensorflow.keras.utils import pad_sequences\n",
    "from tensorflow.keras.models import Sequential"
   ]
  },
  {
   "cell_type": "code",
   "execution_count": 8,
   "metadata": {},
   "outputs": [],
   "source": [
    "import numpy as np"
   ]
  },
  {
   "cell_type": "code",
   "execution_count": 9,
   "metadata": {},
   "outputs": [
    {
     "name": "stdout",
     "output_type": "stream",
     "text": [
      "[[   0    0    0    0 9316 6867 9597 4588]\n",
      " [   0    0    0    0 9316 6867 9597 4372]\n",
      " [   0    0    0    0 9316 8449 9597 4096]\n",
      " [   0    0    0 2041 3550  917 4338 8682]\n",
      " [   0    0    0 2041 3550  917 4338  521]\n",
      " [   0    0    0 7337 9316 2472 9597 4527]\n",
      " [   0    0    0    0  805 9120 9538 4338]]\n"
     ]
    }
   ],
   "source": [
    "#set max sentence length for simple RNN\n",
    "sent_length=8\n",
    "embedded_docs=pad_sequences(one_hot_repr,padding='pre',maxlen=sent_length)\n",
    "print(embedded_docs)\n"
   ]
  },
  {
   "cell_type": "code",
   "execution_count": 10,
   "metadata": {},
   "outputs": [],
   "source": [
    "## feature representation\n",
    "dim=10"
   ]
  },
  {
   "cell_type": "code",
   "execution_count": 11,
   "metadata": {},
   "outputs": [
    {
     "name": "stderr",
     "output_type": "stream",
     "text": [
      "c:\\Python312\\Lib\\site-packages\\keras\\src\\layers\\core\\embedding.py:90: UserWarning: Argument `input_length` is deprecated. Just remove it.\n",
      "  warnings.warn(\n"
     ]
    }
   ],
   "source": [
    "#Creating embedded layer for model and train it\n",
    "# Define model\n",
    "model = Sequential()\n",
    "model.add(Embedding(voc_size,dim,input_length = sent_length))  # No need for input_length\n",
    "model.compile('adam','mse')\n"
   ]
  },
  {
   "cell_type": "code",
   "execution_count": 15,
   "metadata": {},
   "outputs": [
    {
     "data": {
      "text/html": [
       "<pre style=\"white-space:pre;overflow-x:auto;line-height:normal;font-family:Menlo,'DejaVu Sans Mono',consolas,'Courier New',monospace\"><span style=\"font-weight: bold\">Model: \"sequential_2\"</span>\n",
       "</pre>\n"
      ],
      "text/plain": [
       "\u001b[1mModel: \"sequential_2\"\u001b[0m\n"
      ]
     },
     "metadata": {},
     "output_type": "display_data"
    },
    {
     "data": {
      "text/html": [
       "<pre style=\"white-space:pre;overflow-x:auto;line-height:normal;font-family:Menlo,'DejaVu Sans Mono',consolas,'Courier New',monospace\">┏━━━━━━━━━━━━━━━━━━━━━━━━━━━━━━━━━┳━━━━━━━━━━━━━━━━━━━━━━━━┳━━━━━━━━━━━━━━━┓\n",
       "┃<span style=\"font-weight: bold\"> Layer (type)                    </span>┃<span style=\"font-weight: bold\"> Output Shape           </span>┃<span style=\"font-weight: bold\">       Param # </span>┃\n",
       "┡━━━━━━━━━━━━━━━━━━━━━━━━━━━━━━━━━╇━━━━━━━━━━━━━━━━━━━━━━━━╇━━━━━━━━━━━━━━━┩\n",
       "│ embedding_2 (<span style=\"color: #0087ff; text-decoration-color: #0087ff\">Embedding</span>)         │ ?                      │   <span style=\"color: #00af00; text-decoration-color: #00af00\">0</span> (unbuilt) │\n",
       "└─────────────────────────────────┴────────────────────────┴───────────────┘\n",
       "</pre>\n"
      ],
      "text/plain": [
       "┏━━━━━━━━━━━━━━━━━━━━━━━━━━━━━━━━━┳━━━━━━━━━━━━━━━━━━━━━━━━┳━━━━━━━━━━━━━━━┓\n",
       "┃\u001b[1m \u001b[0m\u001b[1mLayer (type)                   \u001b[0m\u001b[1m \u001b[0m┃\u001b[1m \u001b[0m\u001b[1mOutput Shape          \u001b[0m\u001b[1m \u001b[0m┃\u001b[1m \u001b[0m\u001b[1m      Param #\u001b[0m\u001b[1m \u001b[0m┃\n",
       "┡━━━━━━━━━━━━━━━━━━━━━━━━━━━━━━━━━╇━━━━━━━━━━━━━━━━━━━━━━━━╇━━━━━━━━━━━━━━━┩\n",
       "│ embedding_2 (\u001b[38;5;33mEmbedding\u001b[0m)         │ ?                      │   \u001b[38;5;34m0\u001b[0m (unbuilt) │\n",
       "└─────────────────────────────────┴────────────────────────┴───────────────┘\n"
      ]
     },
     "metadata": {},
     "output_type": "display_data"
    },
    {
     "data": {
      "text/html": [
       "<pre style=\"white-space:pre;overflow-x:auto;line-height:normal;font-family:Menlo,'DejaVu Sans Mono',consolas,'Courier New',monospace\"><span style=\"font-weight: bold\"> Total params: </span><span style=\"color: #00af00; text-decoration-color: #00af00\">0</span> (0.00 B)\n",
       "</pre>\n"
      ],
      "text/plain": [
       "\u001b[1m Total params: \u001b[0m\u001b[38;5;34m0\u001b[0m (0.00 B)\n"
      ]
     },
     "metadata": {},
     "output_type": "display_data"
    },
    {
     "data": {
      "text/html": [
       "<pre style=\"white-space:pre;overflow-x:auto;line-height:normal;font-family:Menlo,'DejaVu Sans Mono',consolas,'Courier New',monospace\"><span style=\"font-weight: bold\"> Trainable params: </span><span style=\"color: #00af00; text-decoration-color: #00af00\">0</span> (0.00 B)\n",
       "</pre>\n"
      ],
      "text/plain": [
       "\u001b[1m Trainable params: \u001b[0m\u001b[38;5;34m0\u001b[0m (0.00 B)\n"
      ]
     },
     "metadata": {},
     "output_type": "display_data"
    },
    {
     "data": {
      "text/html": [
       "<pre style=\"white-space:pre;overflow-x:auto;line-height:normal;font-family:Menlo,'DejaVu Sans Mono',consolas,'Courier New',monospace\"><span style=\"font-weight: bold\"> Non-trainable params: </span><span style=\"color: #00af00; text-decoration-color: #00af00\">0</span> (0.00 B)\n",
       "</pre>\n"
      ],
      "text/plain": [
       "\u001b[1m Non-trainable params: \u001b[0m\u001b[38;5;34m0\u001b[0m (0.00 B)\n"
      ]
     },
     "metadata": {},
     "output_type": "display_data"
    }
   ],
   "source": [
    "model.summary()"
   ]
  },
  {
   "cell_type": "code",
   "execution_count": 16,
   "metadata": {},
   "outputs": [
    {
     "ename": "InvalidArgumentError",
     "evalue": "Graph execution error:\n\nDetected at node sequential_2_1/embedding_2_1/GatherV2 defined at (most recent call last):\n  File \"<frozen runpy>\", line 198, in _run_module_as_main\n\n  File \"<frozen runpy>\", line 88, in _run_code\n\n  File \"C:\\Users\\nrageswari\\AppData\\Roaming\\Python\\Python312\\site-packages\\ipykernel_launcher.py\", line 18, in <module>\n\n  File \"C:\\Users\\nrageswari\\AppData\\Roaming\\Python\\Python312\\site-packages\\traitlets\\config\\application.py\", line 1075, in launch_instance\n\n  File \"C:\\Users\\nrageswari\\AppData\\Roaming\\Python\\Python312\\site-packages\\ipykernel\\kernelapp.py\", line 739, in start\n\n  File \"C:\\Users\\nrageswari\\AppData\\Roaming\\Python\\Python312\\site-packages\\tornado\\platform\\asyncio.py\", line 205, in start\n\n  File \"c:\\Python312\\Lib\\asyncio\\base_events.py\", line 639, in run_forever\n\n  File \"c:\\Python312\\Lib\\asyncio\\base_events.py\", line 1985, in _run_once\n\n  File \"c:\\Python312\\Lib\\asyncio\\events.py\", line 88, in _run\n\n  File \"C:\\Users\\nrageswari\\AppData\\Roaming\\Python\\Python312\\site-packages\\ipykernel\\kernelbase.py\", line 545, in dispatch_queue\n\n  File \"C:\\Users\\nrageswari\\AppData\\Roaming\\Python\\Python312\\site-packages\\ipykernel\\kernelbase.py\", line 534, in process_one\n\n  File \"C:\\Users\\nrageswari\\AppData\\Roaming\\Python\\Python312\\site-packages\\ipykernel\\kernelbase.py\", line 437, in dispatch_shell\n\n  File \"C:\\Users\\nrageswari\\AppData\\Roaming\\Python\\Python312\\site-packages\\ipykernel\\ipkernel.py\", line 362, in execute_request\n\n  File \"C:\\Users\\nrageswari\\AppData\\Roaming\\Python\\Python312\\site-packages\\ipykernel\\kernelbase.py\", line 778, in execute_request\n\n  File \"C:\\Users\\nrageswari\\AppData\\Roaming\\Python\\Python312\\site-packages\\ipykernel\\ipkernel.py\", line 449, in do_execute\n\n  File \"C:\\Users\\nrageswari\\AppData\\Roaming\\Python\\Python312\\site-packages\\ipykernel\\zmqshell.py\", line 549, in run_cell\n\n  File \"C:\\Users\\nrageswari\\AppData\\Roaming\\Python\\Python312\\site-packages\\IPython\\core\\interactiveshell.py\", line 3075, in run_cell\n\n  File \"C:\\Users\\nrageswari\\AppData\\Roaming\\Python\\Python312\\site-packages\\IPython\\core\\interactiveshell.py\", line 3130, in _run_cell\n\n  File \"C:\\Users\\nrageswari\\AppData\\Roaming\\Python\\Python312\\site-packages\\IPython\\core\\async_helpers.py\", line 129, in _pseudo_sync_runner\n\n  File \"C:\\Users\\nrageswari\\AppData\\Roaming\\Python\\Python312\\site-packages\\IPython\\core\\interactiveshell.py\", line 3334, in run_cell_async\n\n  File \"C:\\Users\\nrageswari\\AppData\\Roaming\\Python\\Python312\\site-packages\\IPython\\core\\interactiveshell.py\", line 3517, in run_ast_nodes\n\n  File \"C:\\Users\\nrageswari\\AppData\\Roaming\\Python\\Python312\\site-packages\\IPython\\core\\interactiveshell.py\", line 3577, in run_code\n\n  File \"C:\\Users\\nrageswari\\AppData\\Local\\Temp\\ipykernel_10544\\1706915757.py\", line 2, in <module>\n\n  File \"c:\\Python312\\Lib\\site-packages\\keras\\src\\utils\\traceback_utils.py\", line 117, in error_handler\n\n  File \"c:\\Python312\\Lib\\site-packages\\keras\\src\\backend\\tensorflow\\trainer.py\", line 559, in predict\n\n  File \"c:\\Python312\\Lib\\site-packages\\keras\\src\\backend\\tensorflow\\trainer.py\", line 256, in one_step_on_data_distributed\n\n  File \"c:\\Python312\\Lib\\site-packages\\keras\\src\\backend\\tensorflow\\trainer.py\", line 246, in one_step_on_data\n\n  File \"c:\\Python312\\Lib\\site-packages\\keras\\src\\backend\\tensorflow\\trainer.py\", line 101, in predict_step\n\n  File \"c:\\Python312\\Lib\\site-packages\\keras\\src\\utils\\traceback_utils.py\", line 117, in error_handler\n\n  File \"c:\\Python312\\Lib\\site-packages\\keras\\src\\layers\\layer.py\", line 899, in __call__\n\n  File \"c:\\Python312\\Lib\\site-packages\\keras\\src\\utils\\traceback_utils.py\", line 117, in error_handler\n\n  File \"c:\\Python312\\Lib\\site-packages\\keras\\src\\ops\\operation.py\", line 46, in __call__\n\n  File \"c:\\Python312\\Lib\\site-packages\\keras\\src\\utils\\traceback_utils.py\", line 156, in error_handler\n\n  File \"c:\\Python312\\Lib\\site-packages\\keras\\src\\models\\sequential.py\", line 213, in call\n\n  File \"c:\\Python312\\Lib\\site-packages\\keras\\src\\models\\functional.py\", line 182, in call\n\n  File \"c:\\Python312\\Lib\\site-packages\\keras\\src\\ops\\function.py\", line 171, in _run_through_graph\n\n  File \"c:\\Python312\\Lib\\site-packages\\keras\\src\\models\\functional.py\", line 632, in call\n\n  File \"c:\\Python312\\Lib\\site-packages\\keras\\src\\utils\\traceback_utils.py\", line 117, in error_handler\n\n  File \"c:\\Python312\\Lib\\site-packages\\keras\\src\\layers\\layer.py\", line 899, in __call__\n\n  File \"c:\\Python312\\Lib\\site-packages\\keras\\src\\utils\\traceback_utils.py\", line 117, in error_handler\n\n  File \"c:\\Python312\\Lib\\site-packages\\keras\\src\\ops\\operation.py\", line 46, in __call__\n\n  File \"c:\\Python312\\Lib\\site-packages\\keras\\src\\utils\\traceback_utils.py\", line 156, in error_handler\n\n  File \"c:\\Python312\\Lib\\site-packages\\keras\\src\\layers\\core\\embedding.py\", line 140, in call\n\n  File \"c:\\Python312\\Lib\\site-packages\\keras\\src\\ops\\numpy.py\", line 5239, in take\n\n  File \"c:\\Python312\\Lib\\site-packages\\keras\\src\\backend\\tensorflow\\numpy.py\", line 2063, in take\n\nindices[0,4] = 9316 is not in [0, 5000)\n\t [[{{node sequential_2_1/embedding_2_1/GatherV2}}]] [Op:__inference_one_step_on_data_distributed_192]",
     "output_type": "error",
     "traceback": [
      "\u001b[1;31m---------------------------------------------------------------------------\u001b[0m",
      "\u001b[1;31mInvalidArgumentError\u001b[0m                      Traceback (most recent call last)",
      "Cell \u001b[1;32mIn[16], line 2\u001b[0m\n\u001b[0;32m      1\u001b[0m \u001b[38;5;66;03m#predict the embedding words\u001b[39;00m\n\u001b[1;32m----> 2\u001b[0m \u001b[43mmodel\u001b[49m\u001b[38;5;241;43m.\u001b[39;49m\u001b[43mpredict\u001b[49m\u001b[43m(\u001b[49m\u001b[43membedded_docs\u001b[49m\u001b[43m)\u001b[49m\n",
      "File \u001b[1;32mc:\\Python312\\Lib\\site-packages\\keras\\src\\utils\\traceback_utils.py:122\u001b[0m, in \u001b[0;36mfilter_traceback.<locals>.error_handler\u001b[1;34m(*args, **kwargs)\u001b[0m\n\u001b[0;32m    119\u001b[0m     filtered_tb \u001b[38;5;241m=\u001b[39m _process_traceback_frames(e\u001b[38;5;241m.\u001b[39m__traceback__)\n\u001b[0;32m    120\u001b[0m     \u001b[38;5;66;03m# To get the full stack trace, call:\u001b[39;00m\n\u001b[0;32m    121\u001b[0m     \u001b[38;5;66;03m# `keras.config.disable_traceback_filtering()`\u001b[39;00m\n\u001b[1;32m--> 122\u001b[0m     \u001b[38;5;28;01mraise\u001b[39;00m e\u001b[38;5;241m.\u001b[39mwith_traceback(filtered_tb) \u001b[38;5;28;01mfrom\u001b[39;00m \u001b[38;5;28;01mNone\u001b[39;00m\n\u001b[0;32m    123\u001b[0m \u001b[38;5;28;01mfinally\u001b[39;00m:\n\u001b[0;32m    124\u001b[0m     \u001b[38;5;28;01mdel\u001b[39;00m filtered_tb\n",
      "File \u001b[1;32mc:\\Python312\\Lib\\site-packages\\tensorflow\\python\\eager\\execute.py:53\u001b[0m, in \u001b[0;36mquick_execute\u001b[1;34m(op_name, num_outputs, inputs, attrs, ctx, name)\u001b[0m\n\u001b[0;32m     51\u001b[0m \u001b[38;5;28;01mtry\u001b[39;00m:\n\u001b[0;32m     52\u001b[0m   ctx\u001b[38;5;241m.\u001b[39mensure_initialized()\n\u001b[1;32m---> 53\u001b[0m   tensors \u001b[38;5;241m=\u001b[39m pywrap_tfe\u001b[38;5;241m.\u001b[39mTFE_Py_Execute(ctx\u001b[38;5;241m.\u001b[39m_handle, device_name, op_name,\n\u001b[0;32m     54\u001b[0m                                       inputs, attrs, num_outputs)\n\u001b[0;32m     55\u001b[0m \u001b[38;5;28;01mexcept\u001b[39;00m core\u001b[38;5;241m.\u001b[39m_NotOkStatusException \u001b[38;5;28;01mas\u001b[39;00m e:\n\u001b[0;32m     56\u001b[0m   \u001b[38;5;28;01mif\u001b[39;00m name \u001b[38;5;129;01mis\u001b[39;00m \u001b[38;5;129;01mnot\u001b[39;00m \u001b[38;5;28;01mNone\u001b[39;00m:\n",
      "\u001b[1;31mInvalidArgumentError\u001b[0m: Graph execution error:\n\nDetected at node sequential_2_1/embedding_2_1/GatherV2 defined at (most recent call last):\n  File \"<frozen runpy>\", line 198, in _run_module_as_main\n\n  File \"<frozen runpy>\", line 88, in _run_code\n\n  File \"C:\\Users\\nrageswari\\AppData\\Roaming\\Python\\Python312\\site-packages\\ipykernel_launcher.py\", line 18, in <module>\n\n  File \"C:\\Users\\nrageswari\\AppData\\Roaming\\Python\\Python312\\site-packages\\traitlets\\config\\application.py\", line 1075, in launch_instance\n\n  File \"C:\\Users\\nrageswari\\AppData\\Roaming\\Python\\Python312\\site-packages\\ipykernel\\kernelapp.py\", line 739, in start\n\n  File \"C:\\Users\\nrageswari\\AppData\\Roaming\\Python\\Python312\\site-packages\\tornado\\platform\\asyncio.py\", line 205, in start\n\n  File \"c:\\Python312\\Lib\\asyncio\\base_events.py\", line 639, in run_forever\n\n  File \"c:\\Python312\\Lib\\asyncio\\base_events.py\", line 1985, in _run_once\n\n  File \"c:\\Python312\\Lib\\asyncio\\events.py\", line 88, in _run\n\n  File \"C:\\Users\\nrageswari\\AppData\\Roaming\\Python\\Python312\\site-packages\\ipykernel\\kernelbase.py\", line 545, in dispatch_queue\n\n  File \"C:\\Users\\nrageswari\\AppData\\Roaming\\Python\\Python312\\site-packages\\ipykernel\\kernelbase.py\", line 534, in process_one\n\n  File \"C:\\Users\\nrageswari\\AppData\\Roaming\\Python\\Python312\\site-packages\\ipykernel\\kernelbase.py\", line 437, in dispatch_shell\n\n  File \"C:\\Users\\nrageswari\\AppData\\Roaming\\Python\\Python312\\site-packages\\ipykernel\\ipkernel.py\", line 362, in execute_request\n\n  File \"C:\\Users\\nrageswari\\AppData\\Roaming\\Python\\Python312\\site-packages\\ipykernel\\kernelbase.py\", line 778, in execute_request\n\n  File \"C:\\Users\\nrageswari\\AppData\\Roaming\\Python\\Python312\\site-packages\\ipykernel\\ipkernel.py\", line 449, in do_execute\n\n  File \"C:\\Users\\nrageswari\\AppData\\Roaming\\Python\\Python312\\site-packages\\ipykernel\\zmqshell.py\", line 549, in run_cell\n\n  File \"C:\\Users\\nrageswari\\AppData\\Roaming\\Python\\Python312\\site-packages\\IPython\\core\\interactiveshell.py\", line 3075, in run_cell\n\n  File \"C:\\Users\\nrageswari\\AppData\\Roaming\\Python\\Python312\\site-packages\\IPython\\core\\interactiveshell.py\", line 3130, in _run_cell\n\n  File \"C:\\Users\\nrageswari\\AppData\\Roaming\\Python\\Python312\\site-packages\\IPython\\core\\async_helpers.py\", line 129, in _pseudo_sync_runner\n\n  File \"C:\\Users\\nrageswari\\AppData\\Roaming\\Python\\Python312\\site-packages\\IPython\\core\\interactiveshell.py\", line 3334, in run_cell_async\n\n  File \"C:\\Users\\nrageswari\\AppData\\Roaming\\Python\\Python312\\site-packages\\IPython\\core\\interactiveshell.py\", line 3517, in run_ast_nodes\n\n  File \"C:\\Users\\nrageswari\\AppData\\Roaming\\Python\\Python312\\site-packages\\IPython\\core\\interactiveshell.py\", line 3577, in run_code\n\n  File \"C:\\Users\\nrageswari\\AppData\\Local\\Temp\\ipykernel_10544\\1706915757.py\", line 2, in <module>\n\n  File \"c:\\Python312\\Lib\\site-packages\\keras\\src\\utils\\traceback_utils.py\", line 117, in error_handler\n\n  File \"c:\\Python312\\Lib\\site-packages\\keras\\src\\backend\\tensorflow\\trainer.py\", line 559, in predict\n\n  File \"c:\\Python312\\Lib\\site-packages\\keras\\src\\backend\\tensorflow\\trainer.py\", line 256, in one_step_on_data_distributed\n\n  File \"c:\\Python312\\Lib\\site-packages\\keras\\src\\backend\\tensorflow\\trainer.py\", line 246, in one_step_on_data\n\n  File \"c:\\Python312\\Lib\\site-packages\\keras\\src\\backend\\tensorflow\\trainer.py\", line 101, in predict_step\n\n  File \"c:\\Python312\\Lib\\site-packages\\keras\\src\\utils\\traceback_utils.py\", line 117, in error_handler\n\n  File \"c:\\Python312\\Lib\\site-packages\\keras\\src\\layers\\layer.py\", line 899, in __call__\n\n  File \"c:\\Python312\\Lib\\site-packages\\keras\\src\\utils\\traceback_utils.py\", line 117, in error_handler\n\n  File \"c:\\Python312\\Lib\\site-packages\\keras\\src\\ops\\operation.py\", line 46, in __call__\n\n  File \"c:\\Python312\\Lib\\site-packages\\keras\\src\\utils\\traceback_utils.py\", line 156, in error_handler\n\n  File \"c:\\Python312\\Lib\\site-packages\\keras\\src\\models\\sequential.py\", line 213, in call\n\n  File \"c:\\Python312\\Lib\\site-packages\\keras\\src\\models\\functional.py\", line 182, in call\n\n  File \"c:\\Python312\\Lib\\site-packages\\keras\\src\\ops\\function.py\", line 171, in _run_through_graph\n\n  File \"c:\\Python312\\Lib\\site-packages\\keras\\src\\models\\functional.py\", line 632, in call\n\n  File \"c:\\Python312\\Lib\\site-packages\\keras\\src\\utils\\traceback_utils.py\", line 117, in error_handler\n\n  File \"c:\\Python312\\Lib\\site-packages\\keras\\src\\layers\\layer.py\", line 899, in __call__\n\n  File \"c:\\Python312\\Lib\\site-packages\\keras\\src\\utils\\traceback_utils.py\", line 117, in error_handler\n\n  File \"c:\\Python312\\Lib\\site-packages\\keras\\src\\ops\\operation.py\", line 46, in __call__\n\n  File \"c:\\Python312\\Lib\\site-packages\\keras\\src\\utils\\traceback_utils.py\", line 156, in error_handler\n\n  File \"c:\\Python312\\Lib\\site-packages\\keras\\src\\layers\\core\\embedding.py\", line 140, in call\n\n  File \"c:\\Python312\\Lib\\site-packages\\keras\\src\\ops\\numpy.py\", line 5239, in take\n\n  File \"c:\\Python312\\Lib\\site-packages\\keras\\src\\backend\\tensorflow\\numpy.py\", line 2063, in take\n\nindices[0,4] = 9316 is not in [0, 5000)\n\t [[{{node sequential_2_1/embedding_2_1/GatherV2}}]] [Op:__inference_one_step_on_data_distributed_192]"
     ]
    }
   ],
   "source": [
    "#predict the embedding words\n",
    "model.predict(embedded_docs)"
   ]
  },
  {
   "cell_type": "code",
   "execution_count": 15,
   "metadata": {},
   "outputs": [
    {
     "data": {
      "text/plain": [
       "array([   0,    0,    0,    0, 6859, 5732,  816, 6205])"
      ]
     },
     "execution_count": 15,
     "metadata": {},
     "output_type": "execute_result"
    }
   ],
   "source": [
    "#predict the first sentence\n",
    "embedded_docs[0]"
   ]
  },
  {
   "cell_type": "code",
   "execution_count": 16,
   "metadata": {},
   "outputs": [
    {
     "ename": "ValueError",
     "evalue": "Exception encountered when calling Sequential.call().\n\n\u001b[1mCannot take the length of shape with unknown rank.\u001b[0m\n\nArguments received by Sequential.call():\n  • inputs=tf.Tensor(shape=<unknown>, dtype=int32)\n  • training=False\n  • mask=None",
     "output_type": "error",
     "traceback": [
      "\u001b[1;31m---------------------------------------------------------------------------\u001b[0m",
      "\u001b[1;31mValueError\u001b[0m                                Traceback (most recent call last)",
      "Cell \u001b[1;32mIn[16], line 1\u001b[0m\n\u001b[1;32m----> 1\u001b[0m \u001b[43mmodel\u001b[49m\u001b[38;5;241;43m.\u001b[39;49m\u001b[43mpredict\u001b[49m\u001b[43m(\u001b[49m\u001b[43membedded_docs\u001b[49m\u001b[43m[\u001b[49m\u001b[38;5;241;43m0\u001b[39;49m\u001b[43m]\u001b[49m\u001b[43m)\u001b[49m\n",
      "File \u001b[1;32mc:\\Python312\\Lib\\site-packages\\keras\\src\\utils\\traceback_utils.py:122\u001b[0m, in \u001b[0;36mfilter_traceback.<locals>.error_handler\u001b[1;34m(*args, **kwargs)\u001b[0m\n\u001b[0;32m    119\u001b[0m     filtered_tb \u001b[38;5;241m=\u001b[39m _process_traceback_frames(e\u001b[38;5;241m.\u001b[39m__traceback__)\n\u001b[0;32m    120\u001b[0m     \u001b[38;5;66;03m# To get the full stack trace, call:\u001b[39;00m\n\u001b[0;32m    121\u001b[0m     \u001b[38;5;66;03m# `keras.config.disable_traceback_filtering()`\u001b[39;00m\n\u001b[1;32m--> 122\u001b[0m     \u001b[38;5;28;01mraise\u001b[39;00m e\u001b[38;5;241m.\u001b[39mwith_traceback(filtered_tb) \u001b[38;5;28;01mfrom\u001b[39;00m \u001b[38;5;28;01mNone\u001b[39;00m\n\u001b[0;32m    123\u001b[0m \u001b[38;5;28;01mfinally\u001b[39;00m:\n\u001b[0;32m    124\u001b[0m     \u001b[38;5;28;01mdel\u001b[39;00m filtered_tb\n",
      "File \u001b[1;32mc:\\Python312\\Lib\\site-packages\\keras\\src\\utils\\traceback_utils.py:122\u001b[0m, in \u001b[0;36mfilter_traceback.<locals>.error_handler\u001b[1;34m(*args, **kwargs)\u001b[0m\n\u001b[0;32m    119\u001b[0m     filtered_tb \u001b[38;5;241m=\u001b[39m _process_traceback_frames(e\u001b[38;5;241m.\u001b[39m__traceback__)\n\u001b[0;32m    120\u001b[0m     \u001b[38;5;66;03m# To get the full stack trace, call:\u001b[39;00m\n\u001b[0;32m    121\u001b[0m     \u001b[38;5;66;03m# `keras.config.disable_traceback_filtering()`\u001b[39;00m\n\u001b[1;32m--> 122\u001b[0m     \u001b[38;5;28;01mraise\u001b[39;00m e\u001b[38;5;241m.\u001b[39mwith_traceback(filtered_tb) \u001b[38;5;28;01mfrom\u001b[39;00m \u001b[38;5;28;01mNone\u001b[39;00m\n\u001b[0;32m    123\u001b[0m \u001b[38;5;28;01mfinally\u001b[39;00m:\n\u001b[0;32m    124\u001b[0m     \u001b[38;5;28;01mdel\u001b[39;00m filtered_tb\n",
      "\u001b[1;31mValueError\u001b[0m: Exception encountered when calling Sequential.call().\n\n\u001b[1mCannot take the length of shape with unknown rank.\u001b[0m\n\nArguments received by Sequential.call():\n  • inputs=tf.Tensor(shape=<unknown>, dtype=int32)\n  • training=False\n  • mask=None"
     ]
    }
   ],
   "source": [
    "model.predict(embedded_docs[0])"
   ]
  },
  {
   "cell_type": "code",
   "execution_count": 17,
   "metadata": {},
   "outputs": [
    {
     "ename": "InvalidArgumentError",
     "evalue": "Graph execution error:\n\nDetected at node sequential_2_1/embedding_2_1/GatherV2 defined at (most recent call last):\n  File \"<frozen runpy>\", line 198, in _run_module_as_main\n\n  File \"<frozen runpy>\", line 88, in _run_code\n\n  File \"C:\\Users\\nrageswari\\AppData\\Roaming\\Python\\Python312\\site-packages\\ipykernel_launcher.py\", line 18, in <module>\n\n  File \"C:\\Users\\nrageswari\\AppData\\Roaming\\Python\\Python312\\site-packages\\traitlets\\config\\application.py\", line 1075, in launch_instance\n\n  File \"C:\\Users\\nrageswari\\AppData\\Roaming\\Python\\Python312\\site-packages\\ipykernel\\kernelapp.py\", line 739, in start\n\n  File \"C:\\Users\\nrageswari\\AppData\\Roaming\\Python\\Python312\\site-packages\\tornado\\platform\\asyncio.py\", line 205, in start\n\n  File \"c:\\Python312\\Lib\\asyncio\\base_events.py\", line 639, in run_forever\n\n  File \"c:\\Python312\\Lib\\asyncio\\base_events.py\", line 1985, in _run_once\n\n  File \"c:\\Python312\\Lib\\asyncio\\events.py\", line 88, in _run\n\n  File \"C:\\Users\\nrageswari\\AppData\\Roaming\\Python\\Python312\\site-packages\\ipykernel\\kernelbase.py\", line 545, in dispatch_queue\n\n  File \"C:\\Users\\nrageswari\\AppData\\Roaming\\Python\\Python312\\site-packages\\ipykernel\\kernelbase.py\", line 534, in process_one\n\n  File \"C:\\Users\\nrageswari\\AppData\\Roaming\\Python\\Python312\\site-packages\\ipykernel\\kernelbase.py\", line 437, in dispatch_shell\n\n  File \"C:\\Users\\nrageswari\\AppData\\Roaming\\Python\\Python312\\site-packages\\ipykernel\\ipkernel.py\", line 362, in execute_request\n\n  File \"C:\\Users\\nrageswari\\AppData\\Roaming\\Python\\Python312\\site-packages\\ipykernel\\kernelbase.py\", line 778, in execute_request\n\n  File \"C:\\Users\\nrageswari\\AppData\\Roaming\\Python\\Python312\\site-packages\\ipykernel\\ipkernel.py\", line 449, in do_execute\n\n  File \"C:\\Users\\nrageswari\\AppData\\Roaming\\Python\\Python312\\site-packages\\ipykernel\\zmqshell.py\", line 549, in run_cell\n\n  File \"C:\\Users\\nrageswari\\AppData\\Roaming\\Python\\Python312\\site-packages\\IPython\\core\\interactiveshell.py\", line 3075, in run_cell\n\n  File \"C:\\Users\\nrageswari\\AppData\\Roaming\\Python\\Python312\\site-packages\\IPython\\core\\interactiveshell.py\", line 3130, in _run_cell\n\n  File \"C:\\Users\\nrageswari\\AppData\\Roaming\\Python\\Python312\\site-packages\\IPython\\core\\async_helpers.py\", line 129, in _pseudo_sync_runner\n\n  File \"C:\\Users\\nrageswari\\AppData\\Roaming\\Python\\Python312\\site-packages\\IPython\\core\\interactiveshell.py\", line 3334, in run_cell_async\n\n  File \"C:\\Users\\nrageswari\\AppData\\Roaming\\Python\\Python312\\site-packages\\IPython\\core\\interactiveshell.py\", line 3517, in run_ast_nodes\n\n  File \"C:\\Users\\nrageswari\\AppData\\Roaming\\Python\\Python312\\site-packages\\IPython\\core\\interactiveshell.py\", line 3577, in run_code\n\n  File \"C:\\Users\\nrageswari\\AppData\\Local\\Temp\\ipykernel_10544\\1335612817.py\", line 7, in <module>\n\n  File \"c:\\Python312\\Lib\\site-packages\\keras\\src\\utils\\traceback_utils.py\", line 117, in error_handler\n\n  File \"c:\\Python312\\Lib\\site-packages\\keras\\src\\backend\\tensorflow\\trainer.py\", line 559, in predict\n\n  File \"c:\\Python312\\Lib\\site-packages\\keras\\src\\backend\\tensorflow\\trainer.py\", line 256, in one_step_on_data_distributed\n\n  File \"c:\\Python312\\Lib\\site-packages\\keras\\src\\backend\\tensorflow\\trainer.py\", line 246, in one_step_on_data\n\n  File \"c:\\Python312\\Lib\\site-packages\\keras\\src\\backend\\tensorflow\\trainer.py\", line 101, in predict_step\n\n  File \"c:\\Python312\\Lib\\site-packages\\keras\\src\\utils\\traceback_utils.py\", line 117, in error_handler\n\n  File \"c:\\Python312\\Lib\\site-packages\\keras\\src\\layers\\layer.py\", line 899, in __call__\n\n  File \"c:\\Python312\\Lib\\site-packages\\keras\\src\\utils\\traceback_utils.py\", line 117, in error_handler\n\n  File \"c:\\Python312\\Lib\\site-packages\\keras\\src\\ops\\operation.py\", line 46, in __call__\n\n  File \"c:\\Python312\\Lib\\site-packages\\keras\\src\\utils\\traceback_utils.py\", line 156, in error_handler\n\n  File \"c:\\Python312\\Lib\\site-packages\\keras\\src\\models\\sequential.py\", line 213, in call\n\n  File \"c:\\Python312\\Lib\\site-packages\\keras\\src\\models\\functional.py\", line 182, in call\n\n  File \"c:\\Python312\\Lib\\site-packages\\keras\\src\\ops\\function.py\", line 171, in _run_through_graph\n\n  File \"c:\\Python312\\Lib\\site-packages\\keras\\src\\models\\functional.py\", line 632, in call\n\n  File \"c:\\Python312\\Lib\\site-packages\\keras\\src\\utils\\traceback_utils.py\", line 117, in error_handler\n\n  File \"c:\\Python312\\Lib\\site-packages\\keras\\src\\layers\\layer.py\", line 899, in __call__\n\n  File \"c:\\Python312\\Lib\\site-packages\\keras\\src\\utils\\traceback_utils.py\", line 117, in error_handler\n\n  File \"c:\\Python312\\Lib\\site-packages\\keras\\src\\ops\\operation.py\", line 46, in __call__\n\n  File \"c:\\Python312\\Lib\\site-packages\\keras\\src\\utils\\traceback_utils.py\", line 156, in error_handler\n\n  File \"c:\\Python312\\Lib\\site-packages\\keras\\src\\layers\\core\\embedding.py\", line 140, in call\n\n  File \"c:\\Python312\\Lib\\site-packages\\keras\\src\\ops\\numpy.py\", line 5239, in take\n\n  File \"c:\\Python312\\Lib\\site-packages\\keras\\src\\backend\\tensorflow\\numpy.py\", line 2063, in take\n\nindices[0,4] = 9316 is not in [0, 5000)\n\t [[{{node sequential_2_1/embedding_2_1/GatherV2}}]] [Op:__inference_one_step_on_data_distributed_263]",
     "output_type": "error",
     "traceback": [
      "\u001b[1;31m---------------------------------------------------------------------------\u001b[0m",
      "\u001b[1;31mInvalidArgumentError\u001b[0m                      Traceback (most recent call last)",
      "Cell \u001b[1;32mIn[17], line 7\u001b[0m\n\u001b[0;32m      4\u001b[0m input_data \u001b[38;5;241m=\u001b[39m np\u001b[38;5;241m.\u001b[39mexpand_dims(embedded_docs[\u001b[38;5;241m0\u001b[39m], axis\u001b[38;5;241m=\u001b[39m\u001b[38;5;241m0\u001b[39m)\n\u001b[0;32m      6\u001b[0m \u001b[38;5;66;03m# Predict using the model\u001b[39;00m\n\u001b[1;32m----> 7\u001b[0m output \u001b[38;5;241m=\u001b[39m \u001b[43mmodel\u001b[49m\u001b[38;5;241;43m.\u001b[39;49m\u001b[43mpredict\u001b[49m\u001b[43m(\u001b[49m\u001b[43minput_data\u001b[49m\u001b[43m)\u001b[49m\n\u001b[0;32m      8\u001b[0m \u001b[38;5;28mprint\u001b[39m(output)\n",
      "File \u001b[1;32mc:\\Python312\\Lib\\site-packages\\keras\\src\\utils\\traceback_utils.py:122\u001b[0m, in \u001b[0;36mfilter_traceback.<locals>.error_handler\u001b[1;34m(*args, **kwargs)\u001b[0m\n\u001b[0;32m    119\u001b[0m     filtered_tb \u001b[38;5;241m=\u001b[39m _process_traceback_frames(e\u001b[38;5;241m.\u001b[39m__traceback__)\n\u001b[0;32m    120\u001b[0m     \u001b[38;5;66;03m# To get the full stack trace, call:\u001b[39;00m\n\u001b[0;32m    121\u001b[0m     \u001b[38;5;66;03m# `keras.config.disable_traceback_filtering()`\u001b[39;00m\n\u001b[1;32m--> 122\u001b[0m     \u001b[38;5;28;01mraise\u001b[39;00m e\u001b[38;5;241m.\u001b[39mwith_traceback(filtered_tb) \u001b[38;5;28;01mfrom\u001b[39;00m \u001b[38;5;28;01mNone\u001b[39;00m\n\u001b[0;32m    123\u001b[0m \u001b[38;5;28;01mfinally\u001b[39;00m:\n\u001b[0;32m    124\u001b[0m     \u001b[38;5;28;01mdel\u001b[39;00m filtered_tb\n",
      "File \u001b[1;32mc:\\Python312\\Lib\\site-packages\\tensorflow\\python\\eager\\execute.py:53\u001b[0m, in \u001b[0;36mquick_execute\u001b[1;34m(op_name, num_outputs, inputs, attrs, ctx, name)\u001b[0m\n\u001b[0;32m     51\u001b[0m \u001b[38;5;28;01mtry\u001b[39;00m:\n\u001b[0;32m     52\u001b[0m   ctx\u001b[38;5;241m.\u001b[39mensure_initialized()\n\u001b[1;32m---> 53\u001b[0m   tensors \u001b[38;5;241m=\u001b[39m pywrap_tfe\u001b[38;5;241m.\u001b[39mTFE_Py_Execute(ctx\u001b[38;5;241m.\u001b[39m_handle, device_name, op_name,\n\u001b[0;32m     54\u001b[0m                                       inputs, attrs, num_outputs)\n\u001b[0;32m     55\u001b[0m \u001b[38;5;28;01mexcept\u001b[39;00m core\u001b[38;5;241m.\u001b[39m_NotOkStatusException \u001b[38;5;28;01mas\u001b[39;00m e:\n\u001b[0;32m     56\u001b[0m   \u001b[38;5;28;01mif\u001b[39;00m name \u001b[38;5;129;01mis\u001b[39;00m \u001b[38;5;129;01mnot\u001b[39;00m \u001b[38;5;28;01mNone\u001b[39;00m:\n",
      "\u001b[1;31mInvalidArgumentError\u001b[0m: Graph execution error:\n\nDetected at node sequential_2_1/embedding_2_1/GatherV2 defined at (most recent call last):\n  File \"<frozen runpy>\", line 198, in _run_module_as_main\n\n  File \"<frozen runpy>\", line 88, in _run_code\n\n  File \"C:\\Users\\nrageswari\\AppData\\Roaming\\Python\\Python312\\site-packages\\ipykernel_launcher.py\", line 18, in <module>\n\n  File \"C:\\Users\\nrageswari\\AppData\\Roaming\\Python\\Python312\\site-packages\\traitlets\\config\\application.py\", line 1075, in launch_instance\n\n  File \"C:\\Users\\nrageswari\\AppData\\Roaming\\Python\\Python312\\site-packages\\ipykernel\\kernelapp.py\", line 739, in start\n\n  File \"C:\\Users\\nrageswari\\AppData\\Roaming\\Python\\Python312\\site-packages\\tornado\\platform\\asyncio.py\", line 205, in start\n\n  File \"c:\\Python312\\Lib\\asyncio\\base_events.py\", line 639, in run_forever\n\n  File \"c:\\Python312\\Lib\\asyncio\\base_events.py\", line 1985, in _run_once\n\n  File \"c:\\Python312\\Lib\\asyncio\\events.py\", line 88, in _run\n\n  File \"C:\\Users\\nrageswari\\AppData\\Roaming\\Python\\Python312\\site-packages\\ipykernel\\kernelbase.py\", line 545, in dispatch_queue\n\n  File \"C:\\Users\\nrageswari\\AppData\\Roaming\\Python\\Python312\\site-packages\\ipykernel\\kernelbase.py\", line 534, in process_one\n\n  File \"C:\\Users\\nrageswari\\AppData\\Roaming\\Python\\Python312\\site-packages\\ipykernel\\kernelbase.py\", line 437, in dispatch_shell\n\n  File \"C:\\Users\\nrageswari\\AppData\\Roaming\\Python\\Python312\\site-packages\\ipykernel\\ipkernel.py\", line 362, in execute_request\n\n  File \"C:\\Users\\nrageswari\\AppData\\Roaming\\Python\\Python312\\site-packages\\ipykernel\\kernelbase.py\", line 778, in execute_request\n\n  File \"C:\\Users\\nrageswari\\AppData\\Roaming\\Python\\Python312\\site-packages\\ipykernel\\ipkernel.py\", line 449, in do_execute\n\n  File \"C:\\Users\\nrageswari\\AppData\\Roaming\\Python\\Python312\\site-packages\\ipykernel\\zmqshell.py\", line 549, in run_cell\n\n  File \"C:\\Users\\nrageswari\\AppData\\Roaming\\Python\\Python312\\site-packages\\IPython\\core\\interactiveshell.py\", line 3075, in run_cell\n\n  File \"C:\\Users\\nrageswari\\AppData\\Roaming\\Python\\Python312\\site-packages\\IPython\\core\\interactiveshell.py\", line 3130, in _run_cell\n\n  File \"C:\\Users\\nrageswari\\AppData\\Roaming\\Python\\Python312\\site-packages\\IPython\\core\\async_helpers.py\", line 129, in _pseudo_sync_runner\n\n  File \"C:\\Users\\nrageswari\\AppData\\Roaming\\Python\\Python312\\site-packages\\IPython\\core\\interactiveshell.py\", line 3334, in run_cell_async\n\n  File \"C:\\Users\\nrageswari\\AppData\\Roaming\\Python\\Python312\\site-packages\\IPython\\core\\interactiveshell.py\", line 3517, in run_ast_nodes\n\n  File \"C:\\Users\\nrageswari\\AppData\\Roaming\\Python\\Python312\\site-packages\\IPython\\core\\interactiveshell.py\", line 3577, in run_code\n\n  File \"C:\\Users\\nrageswari\\AppData\\Local\\Temp\\ipykernel_10544\\1335612817.py\", line 7, in <module>\n\n  File \"c:\\Python312\\Lib\\site-packages\\keras\\src\\utils\\traceback_utils.py\", line 117, in error_handler\n\n  File \"c:\\Python312\\Lib\\site-packages\\keras\\src\\backend\\tensorflow\\trainer.py\", line 559, in predict\n\n  File \"c:\\Python312\\Lib\\site-packages\\keras\\src\\backend\\tensorflow\\trainer.py\", line 256, in one_step_on_data_distributed\n\n  File \"c:\\Python312\\Lib\\site-packages\\keras\\src\\backend\\tensorflow\\trainer.py\", line 246, in one_step_on_data\n\n  File \"c:\\Python312\\Lib\\site-packages\\keras\\src\\backend\\tensorflow\\trainer.py\", line 101, in predict_step\n\n  File \"c:\\Python312\\Lib\\site-packages\\keras\\src\\utils\\traceback_utils.py\", line 117, in error_handler\n\n  File \"c:\\Python312\\Lib\\site-packages\\keras\\src\\layers\\layer.py\", line 899, in __call__\n\n  File \"c:\\Python312\\Lib\\site-packages\\keras\\src\\utils\\traceback_utils.py\", line 117, in error_handler\n\n  File \"c:\\Python312\\Lib\\site-packages\\keras\\src\\ops\\operation.py\", line 46, in __call__\n\n  File \"c:\\Python312\\Lib\\site-packages\\keras\\src\\utils\\traceback_utils.py\", line 156, in error_handler\n\n  File \"c:\\Python312\\Lib\\site-packages\\keras\\src\\models\\sequential.py\", line 213, in call\n\n  File \"c:\\Python312\\Lib\\site-packages\\keras\\src\\models\\functional.py\", line 182, in call\n\n  File \"c:\\Python312\\Lib\\site-packages\\keras\\src\\ops\\function.py\", line 171, in _run_through_graph\n\n  File \"c:\\Python312\\Lib\\site-packages\\keras\\src\\models\\functional.py\", line 632, in call\n\n  File \"c:\\Python312\\Lib\\site-packages\\keras\\src\\utils\\traceback_utils.py\", line 117, in error_handler\n\n  File \"c:\\Python312\\Lib\\site-packages\\keras\\src\\layers\\layer.py\", line 899, in __call__\n\n  File \"c:\\Python312\\Lib\\site-packages\\keras\\src\\utils\\traceback_utils.py\", line 117, in error_handler\n\n  File \"c:\\Python312\\Lib\\site-packages\\keras\\src\\ops\\operation.py\", line 46, in __call__\n\n  File \"c:\\Python312\\Lib\\site-packages\\keras\\src\\utils\\traceback_utils.py\", line 156, in error_handler\n\n  File \"c:\\Python312\\Lib\\site-packages\\keras\\src\\layers\\core\\embedding.py\", line 140, in call\n\n  File \"c:\\Python312\\Lib\\site-packages\\keras\\src\\ops\\numpy.py\", line 5239, in take\n\n  File \"c:\\Python312\\Lib\\site-packages\\keras\\src\\backend\\tensorflow\\numpy.py\", line 2063, in take\n\nindices[0,4] = 9316 is not in [0, 5000)\n\t [[{{node sequential_2_1/embedding_2_1/GatherV2}}]] [Op:__inference_one_step_on_data_distributed_263]"
     ]
    }
   ],
   "source": [
    "import numpy as np\n",
    "\n",
    "# Expand dimensions to add a batch size of 1\n",
    "input_data = np.expand_dims(embedded_docs[0], axis=0)\n",
    "\n",
    "# Predict using the model\n",
    "output = model.predict(input_data)\n",
    "print(output)\n"
   ]
  },
  {
   "cell_type": "code",
   "execution_count": null,
   "metadata": {},
   "outputs": [],
   "source": []
  }
 ],
 "metadata": {
  "kernelspec": {
   "display_name": "Python 3",
   "language": "python",
   "name": "python3"
  },
  "language_info": {
   "codemirror_mode": {
    "name": "ipython",
    "version": 3
   },
   "file_extension": ".py",
   "mimetype": "text/x-python",
   "name": "python",
   "nbconvert_exporter": "python",
   "pygments_lexer": "ipython3",
   "version": "3.12.2"
  }
 },
 "nbformat": 4,
 "nbformat_minor": 2
}
